Workbook

Sheet Assumptions
A1: Assumptions & Controls
A3: Setting | B3: Value | C3: Month | D3: S&M Spend ($)
A4: Report Date | B4: 45291 | C4: 44927 | D4: 14000
A5: Gross Margin % | B5: 0.8 | C5: 44958 | D5: 13500
A6: Model Start Month | B6: 44927 | C6: 44986 | D6: 14500
A7: Model End Month | B7: 45261 | C7: 45017 | D7: 15000
A8: Customer Count Check | B8: =COUNTA('Customer Data'!A:A)-1 -> 50 | C8: 45047 | D8: 12800
A9: Current MRR Check | B9: ='Monthly Waterfall'!M15 -> 19852 | C9: 45078 | D9: 12600
C10: 45108 | D10: 13000
C11: 45139 | D11: 13300
C12: 45170 | D12: 11500
C13: 45200 | D13: 11500
C14: 45231 | D14: 11800
C15: 45261 | D15: 12000
A16: Spend model | B16: Mock Sales & Marketing spend inputs for CAC demonstration.

Sheet Customer Data
A1: Customer ID | B1: Customer Name | C1: Industry | D1: Region | E1: Acquisition Channel | F1: Plan Tier | G1: Customer Segment | H1: Billing Frequency | I1: Start Date | J1: Cohort Month | K1: Base Plan MRR ($) | L1: Expansion MRR ($) | M1: Expansion Effective Date | N1: Total MRR @ Full Ramp ($) | O1: Churn Date | P1: Status @ Report Date | Q1: Active @ Report Date? | R1: Contract ARR ($) | S1: Annual Invoice Base ($) | T1: Start Month | U1: Expansion Month | V1: Churn Month | W1: Base Contract End Month | X1: Active End Month
A2: CUST-001 | B2: Company 1 | C2: Fintech | D2: North America | E2: AE Team A | F2: Pro | G2: Mid-Market | H2: Monthly | I2: 44950 | J2: =DATE(YEAR(I2),MONTH(I2),1) -> 44927 | K2: 299 | L2: 62 | M2: 44980 | N2: =K2+L2 -> 361 | P2: =IF(OR(O2="",O2>Assumptions!$B$2),"Active","Churned") -> Active | Q2: =IF(P2="Active","Yes","No") -> Yes | R2: =N2*12 -> 4332 | S2: =IF(H2="Annual",K2*12,0) -> 0 | T2: =DATE(YEAR(I2),MONTH(I2),1) -> 44927 | U2: =IF(M2="","",DATE(YEAR(M2),MONTH(M2),1)) -> 44958 | V2: =IF(O2="","",DATE(YEAR(O2),MONTH(O2),1)) | W2: =IF(H2="Annual",EDATE(T2,12),DATE(2099,12,1)) -> 73020 | X2: =IF(V2="",W2,MIN(V2,W2)) -> 73020
A3: CUST-002 | B3: Company 2 | C3: HealthTech | D3: EMEA | E3: AE Team B | F3: Enterprise | G3: Enterprise | H3: Monthly | I3: 44979 | J3: =DATE(YEAR(I3),MONTH(I3),1) -> 44958 | K3: 799 | L3: 22 | M3: 45024 | N3: =K3+L3 -> 821 | O3: 45117 | P3: =IF(OR(O3="",O3>Assumptions!$B$2),"Active","Churned") -> Active | Q3: =IF(P3="Active","Yes","No") -> Yes | R3: =N3*12 -> 9852 | S3: =IF(H3="Annual",K3*12,0) -> 0 | T3: =DATE(YEAR(I3),MONTH(I3),1) -> 44958 | U3: =IF(M3="","",DATE(YEAR(M3),MONTH(M3),1)) -> 45017 | V3: =IF(O3="","",DATE(YEAR(O3),MONTH(O3),1)) -> 45108 | W3: =IF(H3="Annual",EDATE(T3,12),DATE(2099,12,1)) -> 73020 | X3: =IF(V3="",W3,MIN(V3,W3)) -> 45108
A4: CUST-003 | B4: Company 3 | C4: MarTech | D4: APAC | E4: Partner | F4: Growth | G4: SMB | H4: Monthly | I4: 44929 | J4: =DATE(YEAR(I4),MONTH(I4),1) -> 44927 | K4: 199 | L4: 59 | M4: 44929 | N4: =K4+L4 -> 258 | O4: 44965 | P4: =IF(OR(O4="",O4>Assumptions!$B$2),"Active","Churned") -> Active | Q4: =IF(P4="Active","Yes","No") -> Yes | R4: =N4*12 -> 3096 | S4: =IF(H4="Annual",K4*12,0) -> 0 | T4: =DATE(YEAR(I4),MONTH(I4),1) -> 44927 | U4: =IF(M4="","",DATE(YEAR(M4),MONTH(M4),1)) -> 44927 | V4: =IF(O4="","",DATE(YEAR(O4),MONTH(O4),1)) -> 44958 | W4: =IF(H4="Annual",EDATE(T4,12),DATE(2099,12,1)) -> 73020 | X4: =IF(V4="",W4,MIN(V4,W4)) -> 44958
A5: CUST-004 | B5: Company 4 | C5: EdTech | D5: LATAM | E5: Self-Serve | F5: Business | G5: Mid-Market | H5: Annual | I5: 45115 | J5: =DATE(YEAR(I5),MONTH(I5),1) -> 45108 | K5: 499 | L5: 150 | M5: 45190 | N5: =K5+L5 -> 649 | P5: =IF(OR(O5="",O5>Assumptions!$B$2),"Active","Churned") -> Active | Q5: =IF(P5="Active","Yes","No") -> Yes | R5: =N5*12 -> 7788 | S5: =IF(H5="Annual",K5*12,0) -> 5988 | T5: =DATE(YEAR(I5),MONTH(I5),1) -> 45108 | U5: =IF(M5="","",DATE(YEAR(M5),MONTH(M5),1)) -> 45170 | V5: =IF(O5="","",DATE(YEAR(O5),MONTH(O5),1)) | W5: =IF(H5="Annual",EDATE(T5,12),DATE(2099,12,1)) -> 45474 | X5: =IF(V5="",W5,MIN(V5,W5)) -> 45474
A6: CUST-005 | B6: Company 5 | C6: HRTech | D6: North America | E6: AE Team A | F6: Business | G6: Mid-Market | H6: Monthly | I6: 45008 | J6: =DATE(YEAR(I6),MONTH(I6),1) -> 44986 | K6: 499 | L6: 87 | M6: 45038 | N6: =K6+L6 -> 586 | P6: =IF(OR(O6="",O6>Assumptions!$B$2),"Active","Churned") -> Active | Q6: =IF(P6="Active","Yes","No") -> Yes | R6: =N6*12 -> 7032 | S6: =IF(H6="Annual",K6*12,0) -> 0 | T6: =DATE(YEAR(I6),MONTH(I6),1) -> 44986 | U6: =IF(M6="","",DATE(YEAR(M6),MONTH(M6),1)) -> 45017 | V6: =IF(O6="","",DATE(YEAR(O6),MONTH(O6),1)) | W6: =IF(H6="Annual",EDATE(T6,12),DATE(2099,12,1)) -> 73020 | X6: =IF(V6="",W6,MIN(V6,W6)) -> 73020
A7: CUST-006 | B7: Company 6 | C7: Logistics | D7: EMEA | E7: AE Team B | F7: Pro | G7: Mid-Market | H7: Monthly | I7: 45041 | J7: =DATE(YEAR(I7),MONTH(I7),1) -> 45017 | K7: 299 | L7: 26 | M7: 45086 | N7: =K7+L7 -> 325 | P7: =IF(OR(O7="",O7>Assumptions!$B$2),"Active","Churned") -> Active | Q7: =IF(P7="Active","Yes","No") -> Yes | R7: =N7*12 -> 3900 | S7: =IF(H7="Annual",K7*12,0) -> 0 | T7: =DATE(YEAR(I7),MONTH(I7),1) -> 45017 | U7: =IF(M7="","",DATE(YEAR(M7),MONTH(M7),1)) -> 45078 | V7: =IF(O7="","",DATE(YEAR(O7),MONTH(O7),1)) | W7: =IF(H7="Annual",EDATE(T7,12),DATE(2099,12,1)) -> 73020 | X7: =IF(V7="",W7,MIN(V7,W7)) -> 73020
A8: CUST-007 | B8: Company 7 | C8: PropTech | D8: APAC | E8: Partner | F8: Pro | G8: Mid-Market | H8: Monthly | I8: 44969 | J8: =DATE(YEAR(I8),MONTH(I8),1) -> 44958 | K8: 299 | L8: 154 | M8: 45029 | N8: =K8+L8 -> 453 | P8: =IF(OR(O8="",O8>Assumptions!$B$2),"Active","Churned") -> Active | Q8: =IF(P8="Active","Yes","No") -> Yes | R8: =N8*12 -> 5436 | S8: =IF(H8="Annual",K8*12,0) -> 0 | T8: =DATE(YEAR(I8),MONTH(I8),1) -> 44958 | U8: =IF(M8="","",DATE(YEAR(M8),MONTH(M8),1)) -> 45017 | V8: =IF(O8="","",DATE(YEAR(O8),MONTH(O8),1)) | W8: =IF(H8="Annual",EDATE(T8,12),DATE(2099,12,1)) -> 73020 | X8: =IF(V8="",W8,MIN(V8,W8)) -> 73020
A9: CUST-008 | B9: Company 8 | C9: LegalTech | D9: LATAM | E9: Self-Serve | F9: Starter | G9: SMB | H9: Monthly | I9: 45156 | J9: =DATE(YEAR(I9),MONTH(I9),1) -> 45139 | K9: 99 | L9: 96 | M9: 45231 | N9: =K9+L9 -> 195 | P9: =IF(OR(O9="",O9>Assumptions!$B$2),"Active","Churned") -> Active | Q9: =IF(P9="Active","Yes","No") -> Yes | R9: =N9*12 -> 2340 | S9: =IF(H9="Annual",K9*12,0) -> 0 | T9: =DATE(YEAR(I9),MONTH(I9),1) -> 45139 | U9: =IF(M9="","",DATE(YEAR(M9),MONTH(M9),1)) -> 45231 | V9: =IF(O9="","",DATE(YEAR(O9),MONTH(O9),1)) | W9: =IF(H9="Annual",EDATE(T9,12),DATE(2099,12,1)) -> 73020 | X9: =IF(V9="",W9,MIN(V9,W9)) -> 73020
A10: CUST-009 | B10: Company 9 | C10: Fintech | D10: North America | E10: AE Team A | F10: Growth | G10: SMB | H10: Monthly | I10: 45096 | J10: =DATE(YEAR(I10),MONTH(I10),1) -> 45078 | K10: 199 | L10: 180 | M10: 45126 | N10: =K10+L10 -> 379 | P10: =IF(OR(O10="",O10>Assumptions!$B$2),"Active","Churned") -> Active | Q10: =IF(P10="Active","Yes","No") -> Yes | R10: =N10*12 -> 4548 | S10: =IF(H10="Annual",K10*12,0) -> 0 | T10: =DATE(YEAR(I10),MONTH(I10),1) -> 45078 | U10: =IF(M10="","",DATE(YEAR(M10),MONTH(M10),1)) -> 45108 | V10: =IF(O10="","",DATE(YEAR(O10),MONTH(O10),1)) | W10: =IF(H10="Annual",EDATE(T10,12),DATE(2099,12,1)) -> 73020 | X10: =IF(V10="",W10,MIN(V10,W10)) -> 73020
A11: CUST-010 | B11: Company 10 | C11: HealthTech | D11: EMEA | E11: AE Team B | F11: Pro | G11: Mid-Market | H11: Monthly | I11: 45041 | J11: =DATE(YEAR(I11),MONTH(I11),1) -> 45017 | K11: 299 | L11: 20 | M11: 45086 | N11: =K11+L11 -> 319 | P11: =IF(OR(O11="",O11>Assumptions!$B$2),"Active","Churned") -> Active | Q11: =IF(P11="Active","Yes","No") -> Yes | R11: =N11*12 -> 3828 | S11: =IF(H11="Annual",K11*12,0) -> 0 | T11: =DATE(YEAR(I11),MONTH(I11),1) -> 45017 | U11: =IF(M11="","",DATE(YEAR(M11),MONTH(M11),1)) -> 45078 | V11: =IF(O11="","",DATE(YEAR(O11),MONTH(O11),1)) | W11: =IF(H11="Annual",EDATE(T11,12),DATE(2099,12,1)) -> 73020 | X11: =IF(V11="",W11,MIN(V11,W11)) -> 73020
A12: CUST-011 | B12: Company 11 | C12: MarTech | D12: APAC | E12: Partner | F12: Business | G12: Mid-Market | H12: Monthly | I12: 45116 | J12: =DATE(YEAR(I12),MONTH(I12),1) -> 45108 | K12: 499 | L12: 162 | M12: 45176 | N12: =K12+L12 -> 661 | P12: =IF(OR(O12="",O12>Assumptions!$B$2),"Active","Churned") -> Active | Q12: =IF(P12="Active","Yes","No") -> Yes | R12: =N12*12 -> 7932 | S12: =IF(H12="Annual",K12*12,0) -> 0 | T12: =DATE(YEAR(I12),MONTH(I12),1) -> 45108 | U12: =IF(M12="","",DATE(YEAR(M12),MONTH(M12),1)) -> 45170 | V12: =IF(O12="","",DATE(YEAR(O12),MONTH(O12),1)) | W12: =IF(H12="Annual",EDATE(T12,12),DATE(2099,12,1)) -> 73020 | X12: =IF(V12="",W12,MIN(V12,W12)) -> 73020
A13: CUST-012 | B13: Company 12 | C13: EdTech | D13: LATAM | E13: Self-Serve | F13: Growth | G13: SMB | H13: Monthly | I13: 45089 | J13: =DATE(YEAR(I13),MONTH(I13),1) -> 45078 | K13: 199 | L13: 171 | M13: 45164 | N13: =K13+L13 -> 370 | P13: =IF(OR(O13="",O13>Assumptions!$B$2),"Active","Churned") -> Active | Q13: =IF(P13="Active","Yes","No") -> Yes | R13: =N13*12 -> 4440 | S13: =IF(H13="Annual",K13*12,0) -> 0 | T13: =DATE(YEAR(I13),MONTH(I13),1) -> 45078 | U13: =IF(M13="","",DATE(YEAR(M13),MONTH(M13),1)) -> 45139 | V13: =IF(O13="","",DATE(YEAR(O13),MONTH(O13),1)) | W13: =IF(H13="Annual",EDATE(T13,12),DATE(2099,12,1)) -> 73020 | X13: =IF(V13="",W13,MIN(V13,W13)) -> 73020
A14: CUST-013 | B14: Company 13 | C14: HRTech | D14: North America | E14: AE Team A | F14: Growth | G14: SMB | H14: Monthly | I14: 45003 | J14: =DATE(YEAR(I14),MONTH(I14),1) -> 44986 | K14: 199 | L14: 41 | M14: 45033 | N14: =K14+L14 -> 240 | P14: =IF(OR(O14="",O14>Assumptions!$B$2),"Active","Churned") -> Active | Q14: =IF(P14="Active","Yes","No") -> Yes | R14: =N14*12 -> 2880 | S14: =IF(H14="Annual",K14*12,0) -> 0 | T14: =DATE(YEAR(I14),MONTH(I14),1) -> 44986 | U14: =IF(M14="","",DATE(YEAR(M14),MONTH(M14),1)) -> 45017 | V14: =IF(O14="","",DATE(YEAR(O14),MONTH(O14),1)) | W14: =IF(H14="Annual",EDATE(T14,12),DATE(2099,12,1)) -> 73020 | X14: =IF(V14="",W14,MIN(V14,W14)) -> 73020
A15: CUST-014 | B15: Company 14 | C15: Logistics | D15: EMEA | E15: AE Team B | F15: Enterprise | G15: Enterprise | H15: Annual | I15: 45067 | J15: =DATE(YEAR(I15),MONTH(I15),1) -> 45047 | K15: 799 | L15: 56 | M15: 45112 | N15: =K15+L15 -> 855 | P15: =IF(OR(O15="",O15>Assumptions!$B$2),"Active","Churned") -> Active | Q15: =IF(P15="Active","Yes","No") -> Yes | R15: =N15*12 -> 10260 | S15: =IF(H15="Annual",K15*12,0) -> 9588 | T15: =DATE(YEAR(I15),MONTH(I15),1) -> 45047 | U15: =IF(M15="","",DATE(YEAR(M15),MONTH(M15),1)) -> 45108 | V15: =IF(O15="","",DATE(YEAR(O15),MONTH(O15),1)) | W15: =IF(H15="Annual",EDATE(T15,12),DATE(2099,12,1)) -> 45413 | X15: =IF(V15="",W15,MIN(V15,W15)) -> 45413
A16: CUST-015 | B16: Company 15 | C16: PropTech | D16: APAC | E16: Partner | F16: Starter | G16: SMB | H16: Monthly | I16: 44934 | J16: =DATE(YEAR(I16),MONTH(I16),1) -> 44927 | K16: 99 | L16: 80 | M16: 44994 | N16: =K16+L16 -> 179 | P16: =IF(OR(O16="",O16>Assumptions!$B$2),"Active","Churned") -> Active | Q16: =IF(P16="Active","Yes","No") -> Yes | R16: =N16*12 -> 2148 | S16: =IF(H16="Annual",K16*12,0) -> 0 | T16: =DATE(YEAR(I16),MONTH(I16),1) -> 44927 | U16: =IF(M16="","",DATE(YEAR(M16),MONTH(M16),1)) -> 44986 | V16: =IF(O16="","",DATE(YEAR(O16),MONTH(O16),1)) | W16: =IF(H16="Annual",EDATE(T16,12),DATE(2099,12,1)) -> 73020 | X16: =IF(V16="",W16,MIN(V16,W16)) -> 73020
... A19: CUST-018 | B19: Company 18 | C19: HealthTech | D19: EMEA | E19: AE Team B | F19: Enterprise | G19: Enterprise | H19: Annual | I19: 45040 | J19: =DATE(YEAR(I19),MONTH(I19),1) -> 45017 | K19: 799 | L19: 137 | M19: 45085 | N19: =K19+L19 -> 936 | P19: =IF(OR(O19="",O19>Assumptions!$B$2),"Active","Churned") -> Active | Q19: =IF(P19="Active","Yes","No") -> Yes | R19: =N19*12 -> 11232 | S19: =IF(H19="Annual",K19*12,0) -> 9588 | T19: =DATE(YEAR(I19),MONTH(I19),1) -> 45017 | U19: =IF(M19="","",DATE(YEAR(M19),MONTH(M19),1)) -> 45078 | V19: =IF(O19="","",DATE(YEAR(O19),MONTH(O19),1)) | W19: =IF(H19="Annual",EDATE(T19,12),DATE(2099,12,1)) -> 45383 | X19: =IF(V19="",W19,MIN(V19,W19)) -> 45383
A20: CUST-019 | B20: Company 19 | C20: MarTech | D20: APAC | E20: Partner | F20: Growth | G20: SMB | H20: Monthly | I20: 45119 | J20: =DATE(YEAR(I20),MONTH(I20),1) -> 45108 | K20: 199 | L20: 35 | M20: 45179 | N20: =K20+L20 -> 234 | O20: 45275 | P20: =IF(OR(O20="",O20>Assumptions!$B$2),"Active","Churned") -> Active | Q20: =IF(P20="Active","Yes","No") -> Yes | R20: =N20*12 -> 2808 | S20: =IF(H20="Annual",K20*12,0) -> 0 | T20: =DATE(YEAR(I20),MONTH(I20),1) -> 45108 | U20: =IF(M20="","",DATE(YEAR(M20),MONTH(M20),1)) -> 45170 | V20: =IF(O20="","",DATE(YEAR(O20),MONTH(O20),1)) -> 45261 | W20: =IF(H20="Annual",EDATE(T20,12),DATE(2099,12,1)) -> 73020 | X20: =IF(V20="",W20,MIN(V20,W20)) -> 45261
A21: CUST-020 | B21: Company 20 | C21: EdTech | D21: LATAM | E21: Self-Serve | F21: Starter | G21: SMB | H21: Monthly | I21: 44954 | J21: =DATE(YEAR(I21),MONTH(I21),1) -> 44927 | K21: 99 | L21: 39 | M21: 45029 | N21: =K21+L21 -> 138 | P21: =IF(OR(O21="",O21>Assumptions!$B$2),"Active","Churned") -> Active | Q21: =IF(P21="Active","Yes","No") -> Yes | R21: =N21*12 -> 1656 | S21: =IF(H21="Annual",K21*12,0) -> 0 | T21: =DATE(YEAR(I21),MONTH(I21),1) -> 44927 | U21: =IF(M21="","",DATE(YEAR(M21),MONTH(M21),1)) -> 45017 | V21: =IF(O21="","",DATE(YEAR(O21),MONTH(O21),1)) | W21: =IF(H21="Annual",EDATE(T21,12),DATE(2099,12,1)) -> 73020 | X21: =IF(V21="",W21,MIN(V21,W21)) -> 73020
A22: CUST-021 | B22: Company 21 | C22: HRTech | D22: North America | E22: AE Team A | F22: Starter | G22: SMB | H22: Monthly | I22: 45127 | J22: =DATE(YEAR(I22),MONTH(I22),1) -> 45108 | K22: 99 | L22: 98 | M22: 45157 | N22: =K22+L22 -> 197 | P22: =IF(OR(O22="",O22>Assumptions!$B$2),"Active","Churned") -> Active | Q22: =IF(P22="Active","Yes","No") -> Yes | R22: =N22*12 -> 2364 | S22: =IF(H22="Annual",K22*12,0) -> 0 | T22: =DATE(YEAR(I22),MONTH(I22),1) -> 45108 | U22: =IF(M22="","",DATE(YEAR(M22),MONTH(M22),1)) -> 45139 | V22: =IF(O22="","",DATE(YEAR(O22),MONTH(O22),1)) | W22: =IF(H22="Annual",EDATE(T22,12),DATE(2099,12,1)) -> 73020 | X22: =IF(V22="",W22,MIN(V22,W22)) -> 73020
A23: CUST-022 | B23: Company 22 | C23: Logistics | D23: EMEA | E23: AE Team B | F23: Starter | G23: SMB | H23: Monthly | I23: 45064 | J23: =DATE(YEAR(I23),MONTH(I23),1) -> 45047 | K23: 99 | L23: 174 | M23: 45109 | N23: =K23+L23 -> 273 | P23: =IF(OR(O23="",O23>Assumptions!$B$2),"Active","Churned") -> Active | Q23: =IF(P23="Active","Yes","No") -> Yes | R23: =N23*12 -> 3276 | S23: =IF(H23="Annual",K23*12,0) -> 0 | T23: =DATE(YEAR(I23),MONTH(I23),1) -> 45047 | U23: =IF(M23="","",DATE(YEAR(M23),MONTH(M23),1)) -> 45108 | V23: =IF(O23="","",DATE(YEAR(O23),MONTH(O23),1)) | W23: =IF(H23="Annual",EDATE(T23,12),DATE(2099,12,1)) -> 73020 | X23: =IF(V23="",W23,MIN(V23,W23)) -> 73020
A24: CUST-023 | B24: Company 23 | C24: PropTech | D24: APAC | E24: Partner | F24: Pro | G24: Mid-Market | H24: Monthly | I24: 45071 | J24: =DATE(YEAR(I24),MONTH(I24),1) -> 45047 | K24: 299 | L24: 28 | M24: 45131 | N24: =K24+L24 -> 327 | P24: =IF(OR(O24="",O24>Assumptions!$B$2),"Active","Churned") -> Active | Q24: =IF(P24="Active","Yes","No") -> Yes | R24: =N24*12 -> 3924 | S24: =IF(H24="Annual",K24*12,0) -> 0 | T24: =DATE(YEAR(I24),MONTH(I24),1) -> 45047 | U24: =IF(M24="","",DATE(YEAR(M24),MONTH(M24),1)) -> 45108 | V24: =IF(O24="","",DATE(YEAR(O24),MONTH(O24),1)) | W24: =IF(H24="Annual",EDATE(T24,12),DATE(2099,12,1)) -> 73020 | X24: =IF(V24="",W24,MIN(V24,W24)) -> 73020
A25: CUST-024 | B25: Company 24 | C25: LegalTech | D25: LATAM | E25: Self-Serve | F25: Starter | G25: SMB | H25: Monthly | I25: 45000 | J25: =DATE(YEAR(I25),MONTH(I25),1) -> 44986 | K25: 99 | L25: 184 | M25: 45075 | N25: =K25+L25 -> 283 | P25: =IF(OR(O25="",O25>Assumptions!$B$2),"Active","Churned") -> Active | Q25: =IF(P25="Active","Yes","No") -> Yes | R25: =N25*12 -> 3396 | S25: =IF(H25="Annual",K25*12,0) -> 0 | T25: =DATE(YEAR(I25),MONTH(I25),1) -> 44986 | U25: =IF(M25="","",DATE(YEAR(M25),MONTH(M25),1)) -> 45047 | V25: =IF(O25="","",DATE(YEAR(O25),MONTH(O25),1)) | W25: =IF(H25="Annual",EDATE(T25,12),DATE(2099,12,1)) -> 73020 | X25: =IF(V25="",W25,MIN(V25,W25)) -> 73020
A26: CUST-025 | B26: Company 25 | C26: Fintech | D26: North America | E26: AE Team A | F26: Starter | G26: SMB | H26: Monthly | I26: 45002 | J26: =DATE(YEAR(I26),MONTH(I26),1) -> 44986 | K26: 99 | L26: 160 | M26: 45032 | N26: =K26+L26 -> 259 | P26: =IF(OR(O26="",O26>Assumptions!$B$2),"Active","Churned") -> Active | Q26: =IF(P26="Active","Yes","No") -> Yes | R26: =N26*12 -> 3108 | S26: =IF(H26="Annual",K26*12,0) -> 0 | T26: =DATE(YEAR(I26),MONTH(I26),1) -> 44986 | U26: =IF(M26="","",DATE(YEAR(M26),MONTH(M26),1)) -> 45017 | V26: =IF(O26="","",DATE(YEAR(O26),MONTH(O26),1)) | W26: =IF(H26="Annual",EDATE(T26,12),DATE(2099,12,1)) -> 73020 | X26: =IF(V26="",W26,MIN(V26,W26)) -> 73020
A27: CUST-026 | B27: Company 26 | C27: HealthTech | D27: EMEA | E27: AE Team B | F27: Growth | G27: SMB | H27: Monthly | I27: 44997 | J27: =DATE(YEAR(I27),MONTH(I27),1) -> 44986 | K27: 199 | L27: 138 | M27: 44997 | N27: =K27+L27 -> 337 | O27: 45027 | P27: =IF(OR(O27="",O27>Assumptions!$B$2),"Active","Churned") -> Active | Q27: =IF(P27="Active","Yes","No") -> Yes | R27: =N27*12 -> 4044 | S27: =IF(H27="Annual",K27*12,0) -> 0 | T27: =DATE(YEAR(I27),MONTH(I27),1) -> 44986 | U27: =IF(M27="","",DATE(YEAR(M27),MONTH(M27),1)) -> 44986 | V27: =IF(O27="","",DATE(YEAR(O27),MONTH(O27),1)) -> 45017 | W27: =IF(H27="Annual",EDATE(T27,12),DATE(2099,12,1)) -> 73020 | X27: =IF(V27="",W27,MIN(V27,W27)) -> 45017
A28: CUST-027 | B28: Company 27 | C28: MarTech | D28: APAC | E28: Partner | F28: Starter | G28: SMB | H28: Monthly | I28: 45139 | J28: =DATE(YEAR(I28),MONTH(I28),1) -> 45139 | K28: 99 | L28: 92 | M28: 45199 | N28: =K28+L28 -> 191 | P28: =IF(OR(O28="",O28>Assumptions!$B$2),"Active","Churned") -> Active | Q28: =IF(P28="Active","Yes","No") -> Yes | R28: =N28*12 -> 2292 | S28: =IF(H28="Annual",K28*12,0) -> 0 | T28: =DATE(YEAR(I28),MONTH(I28),1) -> 45139 | U28: =IF(M28="","",DATE(YEAR(M28),MONTH(M28),1)) -> 45170 | V28: =IF(O28="","",DATE(YEAR(O28),MONTH(O28),1)) | W28: =IF(H28="Annual",EDATE(T28,12),DATE(2099,12,1)) -> 73020 | X28: =IF(V28="",W28,MIN(V28,W28)) -> 73020
A29: CUST-028 | B29: Company 28 | C29: EdTech | D29: LATAM | E29: Self-Serve | F29: Enterprise | G29: Enterprise | H29: Annual | I29: 44934 | J29: =DATE(YEAR(I29),MONTH(I29),1) -> 44927 | K29: 799 | L29: 20 | M29: 45009 | N29: =K29+L29 -> 819 | P29: =IF(OR(O29="",O29>Assumptions!$B$2),"Active","Churned") -> Active | Q29: =IF(P29="Active","Yes","No") -> Yes | R29: =N29*12 -> 9828 | S29: =IF(H29="Annual",K29*12,0) -> 9588 | T29: =DATE(YEAR(I29),MONTH(I29),1) -> 44927 | U29: =IF(M29="","",DATE(YEAR(M29),MONTH(M29),1)) -> 44986 | V29: =IF(O29="","",DATE(YEAR(O29),MONTH(O29),1)) | W29: =IF(H29="Annual",EDATE(T29,12),DATE(2099,12,1)) -> 45292 | X29: =IF(V29="",W29,MIN(V29,W29)) -> 45292
A30: CUST-029 | B30: Company 29 | C30: HRTech | D30: North America | E30: AE Team A | F30: Enterprise | G30: Enterprise | H30: Annual | I30: 44982 | J30: =DATE(YEAR(I30),MONTH(I30),1) -> 44958 | K30: 799 | L30: 196 | M30: 45012 | N30: =K30+L30 -> 995 | P30: =IF(OR(O30="",O30>Assumptions!$B$2),"Active","Churned") -> Active | Q30: =IF(P30="Active","Yes","No") -> Yes | R30: =N30*12 -> 11940 | S30: =IF(H30="Annual",K30*12,0) -> 9588 | T30: =DATE(YEAR(I30),MONTH(I30),1) -> 44958 | U30: =IF(M30="","",DATE(YEAR(M30),MONTH(M30),1)) -> 44986 | V30: =IF(O30="","",DATE(YEAR(O30),MONTH(O30),1)) | W30: =IF(H30="Annual",EDATE(T30,12),DATE(2099,12,1)) -> 45323 | X30: =IF(V30="",W30,MIN(V30,W30)) -> 45323
A31: CUST-030 | B31: Company 30 | C31: Logistics | D31: EMEA | E31: AE Team B | F31: Growth | G31: SMB | H31: Monthly | I31: 45156 | J31: =DATE(YEAR(I31),MONTH(I31),1) -> 45139 | K31: 199 | L31: 67 | M31: 45201 | N31: =K31+L31 -> 266 | O31: 45294 | P31: =IF(OR(O31="",O31>Assumptions!$B$2),"Active","Churned") -> Active | Q31: =IF(P31="Active","Yes","No") -> Yes | R31: =N31*12 -> 3192 | S31: =IF(H31="Annual",K31*12,0) -> 0 | T31: =DATE(YEAR(I31),MONTH(I31),1) -> 45139 | U31: =IF(M31="","",DATE(YEAR(M31),MONTH(M31),1)) -> 45200 | V31: =IF(O31="","",DATE(YEAR(O31),MONTH(O31),1)) -> 45292 | W31: =IF(H31="Annual",EDATE(T31,12),DATE(2099,12,1)) -> 73020 | X31: =IF(V31="",W31,MIN(V31,W31)) -> 45292
A32: CUST-031 | B32: Company 31 | C32: PropTech | D32: APAC | E32: Partner | F32: Pro | G32: Mid-Market | H32: Monthly | I32: 45039 | J32: =DATE(YEAR(I32),MONTH(I32),1) -> 45017 | K32: 299 | L32: 102 | M32: 45099 | N32: =K32+L32 -> 401 | P32: =IF(OR(O32="",O32>Assumptions!$B$2),"Active","Churned") -> Active | Q32: =IF(P32="Active","Yes","No") -> Yes | R32: =N32*12 -> 4812 | S32: =IF(H32="Annual",K32*12,0) -> 0 | T32: =DATE(YEAR(I32),MONTH(I32),1) -> 45017 | U32: =IF(M32="","",DATE(YEAR(M32),MONTH(M32),1)) -> 45078 | V32: =IF(O32="","",DATE(YEAR(O32),MONTH(O32),1)) | W32: =IF(H32="Annual",EDATE(T32,12),DATE(2099,12,1)) -> 73020 | X32: =IF(V32="",W32,MIN(V32,W32)) -> 73020
A33: CUST-032 | B33: Company 32 | C33: LegalTech | D33: LATAM | E33: Self-Serve | F33: Business | G33: Mid-Market | H33: Annual | I33: 45155 | J33: =DATE(YEAR(I33),MONTH(I33),1) -> 45139 | K33: 499 | L33: 30 | M33: 45230 | N33: =K33+L33 -> 529 | P33: =IF(OR(O33="",O33>Assumptions!$B$2),"Active","Churned") -> Active | Q33: =IF(P33="Active","Yes","No") -> Yes | R33: =N33*12 -> 6348 | S33: =IF(H33="Annual",K33*12,0) -> 5988 | T33: =DATE(YEAR(I33),MONTH(I33),1) -> 45139 | U33: =IF(M33="","",DATE(YEAR(M33),MONTH(M33),1)) -> 45200 | V33: =IF(O33="","",DATE(YEAR(O33),MONTH(O33),1)) | W33: =IF(H33="Annual",EDATE(T33,12),DATE(2099,12,1)) -> 45505 | X33: =IF(V33="",W33,MIN(V33,W33)) -> 45505
A34: CUST-033 | B34: Company 33 | C34: Fintech | D34: North America | E34: AE Team A | F34: Starter | G34: SMB | H34: Monthly | I34: 44968 | J34: =DATE(YEAR(I34),MONTH(I34),1) -> 44958 | K34: 99 | L34: 150 | M34: 44998 | N34: =K34+L34 -> 249 | O34: 45056 | P34: =IF(OR(O34="",O34>Assumptions!$B$2),"Active","Churned") -> Active | Q34: =IF(P34="Active","Yes","No") -> Yes | R34: =N34*12 -> 2988 | S34: =IF(H34="Annual",K34*12,0) -> 0 | T34: =DATE(YEAR(I34),MONTH(I34),1) -> 44958 | U34: =IF(M34="","",DATE(YEAR(M34),MONTH(M34),1)) -> 44986 | V34: =IF(O34="","",DATE(YEAR(O34),MONTH(O34),1)) -> 45047 | W34: =IF(H34="Annual",EDATE(T34,12),DATE(2099,12,1)) -> 73020 | X34: =IF(V34="",W34,MIN(V34,W34)) -> 45047
A35: CUST-034 | B35: Company 34 | C35: HealthTech | D35: EMEA | E35: AE Team B | F35: Starter | G35: SMB | H35: Monthly | I35: 44929 | J35: =DATE(YEAR(I35),MONTH(I35),1) -> 44927 | K35: 99 | L35: 58 | M35: 44974 | N35: =K35+L35 -> 157 | P35: =IF(OR(O35="",O35>Assumptions!$B$2),"Active","Churned") -> Active | Q35: =IF(P35="Active","Yes","No") -> Yes | R35: =N35*12 -> 1884 | S35: =IF(H35="Annual",K35*12,0) -> 0 | T35: =DATE(YEAR(I35),MONTH(I35),1) -> 44927 | U35: =IF(M35="","",DATE(YEAR(M35),MONTH(M35),1)) -> 44958 | V35: =IF(O35="","",DATE(YEAR(O35),MONTH(O35),1)) | W35: =IF(H35="Annual",EDATE(T35,12),DATE(2099,12,1)) -> 73020 | X35: =IF(V35="",W35,MIN(V35,W35)) -> 73020
A36: CUST-035 | B36: Company 35 | C36: MarTech | D36: APAC | E36: Partner | F36: Enterprise | G36: Enterprise | H36: Annual | I36: 45080 | J36: =DATE(YEAR(I36),MONTH(I36),1) -> 45078 | K36: 799 | L36: 60 | M36: 45140 | N36: =K36+L36 -> 859 | P36: =IF(OR(O36="",O36>Assumptions!$B$2),"Active","Churned") -> Active | Q36: =IF(P36="Active","Yes","No") -> Yes | R36: =N36*12 -> 10308 | S36: =IF(H36="Annual",K36*12,0) -> 9588 | T36: =DATE(YEAR(I36),MONTH(I36),1) -> 45078 | U36: =IF(M36="","",DATE(YEAR(M36),MONTH(M36),1)) -> 45139 | V36: =IF(O36="","",DATE(YEAR(O36),MONTH(O36),1)) | W36: =IF(H36="Annual",EDATE(T36,12),DATE(2099,12,1)) -> 45444 | X36: =IF(V36="",W36,MIN(V36,W36)) -> 45444
A37: CUST-036 | B37: Company 36 | C37: EdTech | D37: LATAM | E37: Self-Serve | F37: Growth | G37: SMB | H37: Monthly | I37: 45034 | J37: =DATE(YEAR(I37),MONTH(I37),1) -> 45017 | K37: 199 | L37: 185 | M37: 45109 | N37: =K37+L37 -> 384 | O37: 45211 | P37: =IF(OR(O37="",O37>Assumptions!$B$2),"Active","Churned") -> Active | Q37: =IF(P37="Active","Yes","No") -> Yes | R37: =N37*12 -> 4608 | S37: =IF(H37="Annual",K37*12,0) -> 0 | T37: =DATE(YEAR(I37),MONTH(I37),1) -> 45017 | U37: =IF(M37="","",DATE(YEAR(M37),MONTH(M37),1)) -> 45108 | V37: =IF(O37="","",DATE(YEAR(O37),MONTH(O37),1)) -> 45200 | W37: =IF(H37="Annual",EDATE(T37,12),DATE(2099,12,1)) -> 73020 | X37: =IF(V37="",W37,MIN(V37,W37)) -> 45200
A38: CUST-037 | B38: Company 37 | C38: HRTech | D38: North America | E38: AE Team A | F38: Business | G38: Mid-Market | H38: Monthly | I38: 45042 | J38: =DATE(YEAR(I38),MONTH(I38),1) -> 45017 | K38: 499 | L38: 104 | M38: 45072 | N38: =K38+L38 -> 603 | P38: =IF(OR(O38="",O38>Assumptions!$B$2),"Active","Churned") -> Active | Q38: =IF(P38="Active","Yes","No") -> Yes | R38: =N38*12 -> 7236 | S38: =IF(H38="Annual",K38*12,0) -> 0 | T38: =DATE(YEAR(I38),MONTH(I38),1) -> 45017 | U38: =IF(M38="","",DATE(YEAR(M38),MONTH(M38),1)) -> 45047 | V38: =IF(O38="","",DATE(YEAR(O38),MONTH(O38),1)) | W38: =IF(H38="Annual",EDATE(T38,12),DATE(2099,12,1)) -> 73020 | X38: =IF(V38="",W38,MIN(V38,W38)) -> 73020
A39: CUST-038 | B39: Company 38 | C39: Logistics | D39: EMEA | E39: AE Team B | F39: Business | G39: Mid-Market | H39: Annual | I39: 44979 | J39: =DATE(YEAR(I39),MONTH(I39),1) -> 44958 | K39: 499 | L39: 90 | M39: 45024 | N39: =K39+L39 -> 589 | P39: =IF(OR(O39="",O39>Assumptions!$B$2),"Active","Churned") -> Active | Q39: =IF(P39="Active","Yes","No") -> Yes | R39: =N39*12 -> 7068 | S39: =IF(H39="Annual",K39*12,0) -> 5988 | T39: =DATE(YEAR(I39),MONTH(I39),1) -> 44958 | U39: =IF(M39="","",DATE(YEAR(M39),MONTH(M39),1)) -> 45017 | V39: =IF(O39="","",DATE(YEAR(O39),MONTH(O39),1)) | W39: =IF(H39="Annual",EDATE(T39,12),DATE(2099,12,1)) -> 45323 | X39: =IF(V39="",W39,MIN(V39,W39)) -> 45323
A40: CUST-039 | B40: Company 39 | C40: PropTech | D40: APAC | E40: Partner | F40: Starter | G40: SMB | H40: Monthly | I40: 45166 | J40: =DATE(YEAR(I40),MONTH(I40),1) -> 45139 | K40: 99 | L40: 172 | M40: 45226 | N40: =K40+L40 -> 271 | P40: =IF(OR(O40="",O40>Assumptions!$B$2),"Active","Churned") -> Active | Q40: =IF(P40="Active","Yes","No") -> Yes | R40: =N40*12 -> 3252 | S40: =IF(H40="Annual",K40*12,0) -> 0 | T40: =DATE(YEAR(I40),MONTH(I40),1) -> 45139 | U40: =IF(M40="","",DATE(YEAR(M40),MONTH(M40),1)) -> 45200 | V40: =IF(O40="","",DATE(YEAR(O40),MONTH(O40),1)) | W40: =IF(H40="Annual",EDATE(T40,12),DATE(2099,12,1)) -> 73020 | X40: =IF(V40="",W40,MIN(V40,W40)) -> 73020
A41: CUST-040 | B41: Company 40 | C41: LegalTech | D41: LATAM | E41: Self-Serve | F41: Pro | G41: Mid-Market | H41: Monthly | I41: 44939 | J41: =DATE(YEAR(I41),MONTH(I41),1) -> 44927 | K41: 299 | L41: 27 | M41: 45014 | N41: =K41+L41 -> 326 | P41: =IF(OR(O41="",O41>Assumptions!$B$2),"Active","Churned") -> Active | Q41: =IF(P41="Active","Yes","No") -> Yes | R41: =N41*12 -> 3912 | S41: =IF(H41="Annual",K41*12,0) -> 0 | T41: =DATE(YEAR(I41),MONTH(I41),1) -> 44927 | U41: =IF(M41="","",DATE(YEAR(M41),MONTH(M41),1)) -> 44986 | V41: =IF(O41="","",DATE(YEAR(O41),MONTH(O41),1)) | W41: =IF(H41="Annual",EDATE(T41,12),DATE(2099,12,1)) -> 73020 | X41: =IF(V41="",W41,MIN(V41,W41)) -> 73020
A42: CUST-041 | B42: Company 41 | C42: Fintech | D42: North America | E42: AE Team A | F42: Business | G42: Mid-Market | H42: Monthly | I42: 45034 | J42: =DATE(YEAR(I42),MONTH(I42),1) -> 45017 | K42: 499 | L42: 35 | M42: 45064 | N42: =K42+L42 -> 534 | P42: =IF(OR(O42="",O42>Assumptions!$B$2),"Active","Churned") -> Active | Q42: =IF(P42="Active","Yes","No") -> Yes | R42: =N42*12 -> 6408 | S42: =IF(H42="Annual",K42*12,0) -> 0 | T42: =DATE(YEAR(I42),MONTH(I42),1) -> 45017 | U42: =IF(M42="","",DATE(YEAR(M42),MONTH(M42),1)) -> 45047 | V42: =IF(O42="","",DATE(YEAR(O42),MONTH(O42),1)) | W42: =IF(H42="Annual",EDATE(T42,12),DATE(2099,12,1)) -> 73020 | X42: =IF(V42="",W42,MIN(V42,W42)) -> 73020
...

Sheet Monthly Waterfall
A1: Monthly SaaS Waterfall | 2023
B2: 44927 | C2: 44958 | D2: 44986 | E2: 45017 | F2: 45047 | G2: 45078 | H2: 45108 | I2: 45139 | J2: 45170 | K2: 45200 | L2: 45231 | M2: 45261
B3: 44958 | C3: 44986 | D3: 45017 | E3: 45047 | F3: 45078 | G3: 45108 | H3: 45139 | I3: 45170 | J3: 45200 | K3: 45231 | L3: 45261 | M3: 45292
A5: Beginning Customers | B5: 0 | C5: =B8 -> 10 | D5: =C8 -> 15 | E5: =D8 -> 22 | F5: =E8 -> 29 | G5: =F8 -> 32 | H5: =G8 -> 36 | I5: =H8 -> 39 | J5: =I8 -> 46 | ... M5: =L8 -> 45
A6: New Customers | B6: =COUNTIF('Customer Data'!$T$2:$T$51,B$2) -> 10 | C6: =COUNTIF('Customer Data'!$T$2:$T$51,C$2) -> 6 | D6: =COUNTIF('Customer Data'!$T$2:$T$51,D$2) -> 7 | E6: =COUNTIF('Customer Data'!$T$2:$T$51,E$2) -> 8 | F6: =COUNTIF('Customer Data'!$T$2:$T$51,F$2) -> 4 | G6: =COUNTIF('Customer Data'!$T$2:$T$51,G$2) -> 4 | H6: =COUNTIF('Customer Data'!$T$2:$T$51,H$2) -> 4 | I6: =COUNTIF('Customer Data'!$T$2:$T$51,I$2) -> 7 | ... M6: =COUNTIF('Customer Data'!$T$2:$T$51,M$2) -> 0
A7: Churned Customers | B7: =COUNTIF('Customer Data'!$V$2:$V$51,B$2) -> 0 | C7: =COUNTIF('Customer Data'!$V$2:$V$51,C$2) -> 1 | D7: =COUNTIF('Customer Data'!$V$2:$V$51,D$2) -> 0 | E7: =COUNTIF('Customer Data'!$V$2:$V$51,E$2) -> 1 | F7: =COUNTIF('Customer Data'!$V$2:$V$51,F$2) -> 1 | G7: =COUNTIF('Customer Data'!$V$2:$V$51,G$2) -> 0 | H7: =COUNTIF('Customer Data'!$V$2:$V$51,H$2) -> 1 | I7: =COUNTIF('Customer Data'!$V$2:$V$51,I$2) -> 0 | ... M7: =COUNTIF('Customer Data'!$V$2:$V$51,M$2) -> 1
A8: Ending Customers | B8: =B5+B6-B7 -> 10 | C8: =C5+C6-C7 -> 15 | D8: =D5+D6-D7 -> 22 | E8: =E5+E6-E7 -> 29 | F8: =F5+F6-F7 -> 32 | G8: =G5+G6-G7 -> 36 | H8: =H5+H6-H7 -> 39 | I8: =I5+I6-I7 -> 46 | ... M8: =M5+M6-M7 -> 44
A10: Beginning MRR ($) | B10: 0 | C10: =B15 -> 3349 | D10: =C15 -> 6552 | E10: =D15 -> 9059 | F10: =E15 -> 12490 | G10: =F15 -> 14283 | H10: =G15 -> 15883 | I10: =H15 -> 16981 | J10: =I15 -> 19452 | ... M10: =L15 -> 20086
A11: New MRR ($) | B11: =SUMIF('Customer Data'!$T$2:$T$51,B$2,'Customer Data'!$K$2:$K$51) -> 3290 | C11: =SUMIF('Customer Data'!$T$2:$T$51,C$2,'Customer Data'!$K$2:$K$51) -> 3294 | D11: =SUMIF('Customer Data'!$T$2:$T$51,D$2,'Customer Data'!$K$2:$K$51) -> 1893 | E11: =SUMIF('Customer Data'!$T$2:$T$51,E$2,'Customer Data'!$K$2:$K$51) -> 2992 | F11: =SUMIF('Customer Data'!$T$2:$T$51,F$2,'Customer Data'!$K$2:$K$51) -> 1396 | G11: =SUMIF('Customer Data'!$T$2:$T$51,G$2,'Customer Data'!$K$2:$K$51) -> 1296 | H11: =SUMIF('Customer Data'!$T$2:$T$51,H$2,'Customer Data'!$K$2:$K$51) -> 1296 | I11: =SUMIF('Customer Data'!$T$2:$T$51,I$2,'Customer Data'!$K$2:$K$51) -> 1993 | ... M11: =SUMIF('Customer Data'!$T$2:$T$51,M$2,'Customer Data'!$K$2:$K$51) -> 0
A12: Expansion MRR ($) | B12: =SUMIF('Customer Data'!$U$2:$U$51,B$2,'Customer Data'!$L$2:$L$51) -> 59 | C12: =SUMIF('Customer Data'!$U$2:$U$51,C$2,'Customer Data'!$L$2:$L$51) -> 167 | D12: =SUMIF('Customer Data'!$U$2:$U$51,D$2,'Customer Data'!$L$2:$L$51) -> 614 | E12: =SUMIF('Customer Data'!$U$2:$U$51,E$2,'Customer Data'!$L$2:$L$51) -> 776 | F12: =SUMIF('Customer Data'!$U$2:$U$51,F$2,'Customer Data'!$L$2:$L$51) -> 646 | G12: =SUMIF('Customer Data'!$U$2:$U$51,G$2,'Customer Data'!$L$2:$L$51) -> 304 | H12: =SUMIF('Customer Data'!$U$2:$U$51,H$2,'Customer Data'!$L$2:$L$51) -> 623 | I12: =SUMIF('Customer Data'!$U$2:$U$51,I$2,'Customer Data'!$L$2:$L$51) -> 478 | ... M12: =SUMIF('Customer Data'!$U$2:$U$51,M$2,'Customer Data'!$L$2:$L$51) -> 0
A13: Churn MRR ($) | B13: =SUMIF('Customer Data'!$V$2:$V$51,B$2,'Customer Data'!$N$2:$N$51) -> 0 | C13: =SUMIF('Customer Data'!$V$2:$V$51,C$2,'Customer Data'!$N$2:$N$51) -> 258 | D13: =SUMIF('Customer Data'!$V$2:$V$51,D$2,'Customer Data'!$N$2:$N$51) -> 0 | E13: =SUMIF('Customer Data'!$V$2:$V$51,E$2,'Customer Data'!$N$2:$N$51) -> 337 | F13: =SUMIF('Customer Data'!$V$2:$V$51,F$2,'Customer Data'!$N$2:$N$51) -> 249 | G13: =SUMIF('Customer Data'!$V$2:$V$51,G$2,'Customer Data'!$N$2:$N$51) -> 0 | H13: =SUMIF('Customer Data'!$V$2:$V$51,H$2,'Customer Data'!$N$2:$N$51) -> 821 | I13: =SUMIF('Customer Data'!$V$2:$V$51,I$2,'Customer Data'!$N$2:$N$51) -> 0 | ... M13: =SUMIF('Customer Data'!$V$2:$V$51,M$2,'Customer Data'!$N$2:$N$51) -> 234
A14: Net New MRR ($) | B14: =B11+B12-B13 -> 3349 | C14: =C11+C12-C13 -> 3203 | D14: =D11+D12-D13 -> 2507 | E14: =E11+E12-E13 -> 3431 | F14: =F11+F12-F13 -> 1793 | G14: =G11+G12-G13 -> 1600 | H14: =H11+H12-H13 -> 1098 | I14: =I11+I12-I13 -> 2471 | ... M14: =M11+M12-M13 -> -234
A15: Ending MRR ($) | B15: =B10+B14 -> 3349 | C15: =C10+C14 -> 6552 | D15: =D10+D14 -> 9059 | E15: =E10+E14 -> 12490 | F15: =F10+F14 -> 14283 | G15: =G10+G14 -> 15883 | H15: =H10+H14 -> 16981 | I15: =I10+I14 -> 19452 | ... M15: =M10+M14 -> 19852
A17: Logo Churn % | B17: =IF(B5=0,"",B7/B5) | C17: =IF(C5=0,"",C7/C5) -> 0.1 | D17: =IF(D5=0,"",D7/D5) -> 0 | E17: =IF(E5=0,"",E7/E5) -> 0.045454545 | F17: =IF(F5=0,"",F7/F5) -> 0.034482759 | G17: =IF(G5=0,"",G7/G5) -> 0 | H17: =IF(H5=0,"",H7/H5) -> 0.027777778 | I17: =IF(I5=0,"",I7/I5) -> 0 | ... M17: =IF(M5=0,"",M7/M5) -> 0.022222222
A18: MRR Growth % | B18: =IF(B10=0,"",B15/B10-1) | C18: =IF(C10=0,"",C15/C10-1) -> 0.9564049 | D18: =IF(D10=0,"",D15/D10-1) -> 0.38263126 | E18: =IF(E10=0,"",E15/E10-1) -> 0.37873938 | F18: =IF(F10=0,"",F15/F10-1) -> 0.14355484 | G18: =IF(G10=0,"",G15/G10-1) -> 0.11202128 | H18: =IF(H10=0,"",H15/H10-1) -> 0.069130517 | I18: =IF(I10=0,"",I15/I10-1) -> 0.14551558 | ... M18: =IF(M10=0,"",M15/M10-1) -> -0.011649905
A19: NRR | B19: =IF(B10=0,"",(B10+B12-B13)/B10) | C19: =IF(C10=0,"",(C10+C12-C13)/C10) -> 0.97282771 | D19: =IF(D10=0,"",(D10+D12-D13)/D10) -> 1.0937118 | E19: =IF(E10=0,"",(E10+E12-E13)/E10) -> 1.0484601 | F19: =IF(F10=0,"",(F10+F12-F13)/F10) -> 1.0317854 | G19: =IF(G10=0,"",(G10+G12-G13)/G10) -> 1.021284 | H19: =IF(H10=0,"",(H10+H12-H13)/H10) -> 0.98753384 | I19: =IF(I10=0,"",(I10+I12-I13)/I10) -> 1.0281491 | ... M19: =IF(M10=0,"",(M10+M12-M13)/M10) -> 0.98835009
A21: Sales & Marketing Spend ($) | B21: =Assumptions!C4 -> 44927 | C21: =Assumptions!C5 -> 44958 | D21: =Assumptions!C6 -> 44986 | E21: =Assumptions!C7 -> 45017 | F21: =Assumptions!C8 -> 45047 | G21: =Assumptions!C9 -> 45078 | H21: =Assumptions!C10 -> 45108 | I21: =Assumptions!C11 -> 45139 | J21: =Assumptions!C12 -> 45170 | K21: =Assumptions!C13 -> 45200 | L21: =Assumptions!C14 -> 45231 | M21: =Assumptions!C15 -> 45261
A22: CAC / New Customer ($) | B22: =IF(B6=0,"",B21/B6) -> 4492.7 | C22: =IF(C6=0,"",C21/C6) -> 7493 | D22: =IF(D6=0,"",D21/D6) -> 6426.5714 | E22: =IF(E6=0,"",E21/E6) -> 5627.125 | F22: =IF(F6=0,"",F21/F6) -> 11261.75 | G22: =IF(G6=0,"",G21/G6) -> 11269.5 | H22: =IF(H6=0,"",H21/H6) -> 11277 | I22: =IF(I6=0,"",I21/I6) -> 6448.4286 | ... M22: =IF(M6=0,"",M21/M6)
A24: Check | B24: =M15-SUMIF('Customer Data'!$P$2:$P$51,"Active",'Customer Data'!$N$2:$N$51) -> -2283

Sheet Cohort Analysis
A1: Cohort Analysis | Corrected by Actual Start Month
A3: Cohort | B3: Customers | C3: Active @ Report | D3: Churned @ Report | E3: Retention % | F3: Avg Base MRR ($) | G3: Avg Full-Ramp MRR ($) | H3: Annual Contracts | I3: Cohort ARR ($)
A4: 44927 | B4: =COUNTIF('Customer Data'!$J$2:$J$51,$A4) -> 10 | C4: =COUNTIFS('Customer Data'!$J$2:$J$51,$A4,'Customer Data'!$P$2:$P$51,"Active") -> 10 | D4: =B4-C4 -> 0 | E4: =IF(B4=0,"",C4/B4) -> 1 | F4: =IF(B4=0,"",SUMIF('Customer Data'!$J$2:$J$51,$A4,'Customer Data'!$K$2:$K$51)/B4) -> 329 | G4: =IF(B4=0,"",SUMIF('Customer Data'!$J$2:$J$51,$A4,'Customer Data'!$N$2:$N$51)/B4) -> 368.5 | H4: =COUNTIFS('Customer Data'!$J$2:$J$51,$A4,'Customer Data'!$H$2:$H$51,"Annual") -> 2 | I4: =SUMIF('Customer Data'!$J$2:$J$51,$A4,'Customer Data'!$R$2:$R$51) -> 44220
A5: 44958 | B5: =COUNTIF('Customer Data'!$J$2:$J$51,$A5) -> 6 | C5: =COUNTIFS('Customer Data'!$J$2:$J$51,$A5,'Customer Data'!$P$2:$P$51,"Active") -> 6 | D5: =B5-C5 -> 0 | E5: =IF(B5=0,"",C5/B5) -> 1 | F5: =IF(B5=0,"",SUMIF('Customer Data'!$J$2:$J$51,$A5,'Customer Data'!$K$2:$K$51)/B5) -> 549 | G5: =IF(B5=0,"",SUMIF('Customer Data'!$J$2:$J$51,$A5,'Customer Data'!$N$2:$N$51)/B5) -> 681.5 | H5: =COUNTIFS('Customer Data'!$J$2:$J$51,$A5,'Customer Data'!$H$2:$H$51,"Annual") -> 3 | I5: =SUMIF('Customer Data'!$J$2:$J$51,$A5,'Customer Data'!$R$2:$R$51) -> 49068
A6: 44986 | B6: =COUNTIF('Customer Data'!$J$2:$J$51,$A6) -> 7 | C6: =COUNTIFS('Customer Data'!$J$2:$J$51,$A6,'Customer Data'!$P$2:$P$51,"Active") -> 7 | D6: =B6-C6 -> 0 | E6: =IF(B6=0,"",C6/B6) -> 1 | F6: =IF(B6=0,"",SUMIF('Customer Data'!$J$2:$J$51,$A6,'Customer Data'!$K$2:$K$51)/B6) -> 270.42857 | G6: =IF(B6=0,"",SUMIF('Customer Data'!$J$2:$J$51,$A6,'Customer Data'!$N$2:$N$51)/B6) -> 383 | H6: =COUNTIFS('Customer Data'!$J$2:$J$51,$A6,'Customer Data'!$H$2:$H$51,"Annual") -> 1 | I6: =SUMIF('Customer Data'!$J$2:$J$51,$A6,'Customer Data'!$R$2:$R$51) -> 32172
A7: 45017 | B7: =COUNTIF('Customer Data'!$J$2:$J$51,$A7) -> 8 | C7: =COUNTIFS('Customer Data'!$J$2:$J$51,$A7,'Customer Data'!$P$2:$P$51,"Active") -> 8 | D7: =B7-C7 -> 0 | E7: =IF(B7=0,"",C7/B7) -> 1 | F7: =IF(B7=0,"",SUMIF('Customer Data'!$J$2:$J$51,$A7,'Customer Data'!$K$2:$K$51)/B7) -> 374 | G7: =IF(B7=0,"",SUMIF('Customer Data'!$J$2:$J$51,$A7,'Customer Data'!$N$2:$N$51)/B7) -> 468.25 | H7: =COUNTIFS('Customer Data'!$J$2:$J$51,$A7,'Customer Data'!$H$2:$H$51,"Annual") -> 1 | I7: =SUMIF('Customer Data'!$J$2:$J$51,$A7,'Customer Data'!$R$2:$R$51) -> 44952
A8: 45047 | B8: =COUNTIF('Customer Data'!$J$2:$J$51,$A8) -> 4 | C8: =COUNTIFS('Customer Data'!$J$2:$J$51,$A8,'Customer Data'!$P$2:$P$51,"Active") -> 4 | D8: =B8-C8 -> 0 | E8: =IF(B8=0,"",C8/B8) -> 1 | F8: =IF(B8=0,"",SUMIF('Customer Data'!$J$2:$J$51,$A8,'Customer Data'!$K$2:$K$51)/B8) -> 349 | G8: =IF(B8=0,"",SUMIF('Customer Data'!$J$2:$J$51,$A8,'Customer Data'!$N$2:$N$51)/B8) -> 418.25 | H8: =COUNTIFS('Customer Data'!$J$2:$J$51,$A8,'Customer Data'!$H$2:$H$51,"Annual") -> 1 | I8: =SUMIF('Customer Data'!$J$2:$J$51,$A8,'Customer Data'!$R$2:$R$51) -> 20076
A9: 45078 | B9: =COUNTIF('Customer Data'!$J$2:$J$51,$A9) -> 4 | C9: =COUNTIFS('Customer Data'!$J$2:$J$51,$A9,'Customer Data'!$P$2:$P$51,"Active") -> 4 | D9: =B9-C9 -> 0 | E9: =IF(B9=0,"",C9/B9) -> 1 | F9: =IF(B9=0,"",SUMIF('Customer Data'!$J$2:$J$51,$A9,'Customer Data'!$K$2:$K$51)/B9) -> 324 | G9: =IF(B9=0,"",SUMIF('Customer Data'!$J$2:$J$51,$A9,'Customer Data'!$N$2:$N$51)/B9) -> 464 | H9: =COUNTIFS('Customer Data'!$J$2:$J$51,$A9,'Customer Data'!$H$2:$H$51,"Annual") -> 1 | I9: =SUMIF('Customer Data'!$J$2:$J$51,$A9,'Customer Data'!$R$2:$R$51) -> 22272
A10: 45108 | B10: =COUNTIF('Customer Data'!$J$2:$J$51,$A10) -> 4 | C10: =COUNTIFS('Customer Data'!$J$2:$J$51,$A10,'Customer Data'!$P$2:$P$51,"Active") -> 4 | D10: =B10-C10 -> 0 | E10: =IF(B10=0,"",C10/B10) -> 1 | F10: =IF(B10=0,"",SUMIF('Customer Data'!$J$2:$J$51,$A10,'Customer Data'!$K$2:$K$51)/B10) -> 324 | G10: =IF(B10=0,"",SUMIF('Customer Data'!$J$2:$J$51,$A10,'Customer Data'!$N$2:$N$51)/B10) -> 435.25 | H10: =COUNTIFS('Customer Data'!$J$2:$J$51,$A10,'Customer Data'!$H$2:$H$51,"Annual") -> 1 | I10: =SUMIF('Customer Data'!$J$2:$J$51,$A10,'Customer Data'!$R$2:$R$51) -> 20892
A11: 45139 | B11: =COUNTIF('Customer Data'!$J$2:$J$51,$A11) -> 7 | C11: =COUNTIFS('Customer Data'!$J$2:$J$51,$A11,'Customer Data'!$P$2:$P$51,"Active") -> 7 | D11: =B11-C11 -> 0 | E11: =IF(B11=0,"",C11/B11) -> 1 | F11: =IF(B11=0,"",SUMIF('Customer Data'!$J$2:$J$51,$A11,'Customer Data'!$K$2:$K$51)/B11) -> 284.71429 | G11: =IF(B11=0,"",SUMIF('Customer Data'!$J$2:$J$51,$A11,'Customer Data'!$N$2:$N$51)/B11) -> 380.57143 | H11: =COUNTIFS('Customer Data'!$J$2:$J$51,$A11,'Customer Data'!$H$2:$H$51,"Annual") -> 2 | I11: =SUMIF('Customer Data'!$J$2:$J$51,$A11,'Customer Data'!$R$2:$R$51) -> 31968

Sheet Revenue Recognition
A1: Revenue Recognition Schedule | Base Plans Annualized, Add-ons Monthly
A2: Method | B2: Annual customers are billed upfront for base subscription only and recognized ratably by month. Add-ons are billed and recognized monthly for all customers.
B3: 44927 | C3: 44958 | D3: 44986 | E3: 45017 | F3: 45047 | G3: 45078 | H3: 45108 | I3: 45139 | J3: 45170 | K3: 45200 | L3: 45231 | M3: 45261 | N3: 45292 | O3: 45323 | P3: 45352 | Q3: 45383 | R3: 45413 | S3: 45444 | T3: 45474 | U3: 45505 | V3: 45536 | W3: 45566 | X3: 45597 | Y3: 45627
A5: Annual Contract Billings - Base Plan ($) | B5: =SUMIF('Customer Data'!$T$2:$T$51,B$3,'Customer Data'!$S$2:$S$51) -> 19176 | C5: =SUMIF('Customer Data'!$T$2:$T$51,C$3,'Customer Data'!$S$2:$S$51) -> 25164 | D5: =SUMIF('Customer Data'!$T$2:$T$51,D$3,'Customer Data'!$S$2:$S$51) -> 5988 | E5: =SUMIF('Customer Data'!$T$2:$T$51,E$3,'Customer Data'!$S$2:$S$51) -> 9588 | F5: =SUMIF('Customer Data'!$T$2:$T$51,F$3,'Customer Data'!$S$2:$S$51) -> 9588 | G5: =SUMIF('Customer Data'!$T$2:$T$51,G$3,'Customer Data'!$S$2:$S$51) -> 9588 | H5: =SUMIF('Customer Data'!$T$2:$T$51,H$3,'Customer Data'!$S$2:$S$51) -> 5988 | I5: =SUMIF('Customer Data'!$T$2:$T$51,I$3,'Customer Data'!$S$2:$S$51) -> 11976 | ... Y5: =SUMIF('Customer Data'!$T$2:$T$51,Y$3,'Customer Data'!$S$2:$S$51) -> 0
A6: Monthly Billings - Base Plan ($) | B6: =SUMIFS('Customer Data'!$K$2:$K$51,'Customer Data'!$H$2:$H$51,"Monthly",'Customer Data'!$T$2:$T$51,"<="&B$3,'Customer Data'!$X$2:$X$51,">"&B$3) -> 1692 | C6: =SUMIFS('Customer Data'!$K$2:$K$51,'Customer Data'!$H$2:$H$51,"Monthly",'Customer Data'!$T$2:$T$51,"<="&C$3,'Customer Data'!$X$2:$X$51,">"&C$3) -> 2690 | D6: =SUMIFS('Customer Data'!$K$2:$K$51,'Customer Data'!$H$2:$H$51,"Monthly",'Customer Data'!$T$2:$T$51,"<="&D$3,'Customer Data'!$X$2:$X$51,">"&D$3) -> 4084 | E6: =SUMIFS('Customer Data'!$K$2:$K$51,'Customer Data'!$H$2:$H$51,"Monthly",'Customer Data'!$T$2:$T$51,"<="&E$3,'Customer Data'!$X$2:$X$51,">"&E$3) -> 6078 | F6: =SUMIFS('Customer Data'!$K$2:$K$51,'Customer Data'!$H$2:$H$51,"Monthly",'Customer Data'!$T$2:$T$51,"<="&F$3,'Customer Data'!$X$2:$X$51,">"&F$3) -> 6576 | G6: =SUMIFS('Customer Data'!$K$2:$K$51,'Customer Data'!$H$2:$H$51,"Monthly",'Customer Data'!$T$2:$T$51,"<="&G$3,'Customer Data'!$X$2:$X$51,">"&G$3) -> 7073 | H6: =SUMIFS('Customer Data'!$K$2:$K$51,'Customer Data'!$H$2:$H$51,"Monthly",'Customer Data'!$T$2:$T$51,"<="&H$3,'Customer Data'!$X$2:$X$51,">"&H$3) -> 7071 | I6: =SUMIFS('Customer Data'!$K$2:$K$51,'Customer Data'!$H$2:$H$51,"Monthly",'Customer Data'!$T$2:$T$51,"<="&I$3,'Customer Data'!$X$2:$X$51,">"&I$3) -> 8066 | ... Y6: =SUMIFS('Customer Data'!$K$2:$K$51,'Customer Data'!$H$2:$H$51,"Monthly",'Customer Data'!$T$2:$T$51,"<="&Y$3,'Customer Data'!$X$2:$X$51,">"&Y$3) -> 7469
A7: Monthly Billings - Add-ons ($) | B7: =SUMIFS('Customer Data'!$L$2:$L$51,'Customer Data'!$U$2:$U$51,">0",'Customer Data'!$U$2:$U$51,"<="&B$3,'Customer Data'!$X$2:$X$51,">"&B$3) -> 59 | C7: =SUMIFS('Customer Data'!$L$2:$L$51,'Customer Data'!$U$2:$U$51,">0",'Customer Data'!$U$2:$U$51,"<="&C$3,'Customer Data'!$X$2:$X$51,">"&C$3) -> 167 | D7: =SUMIFS('Customer Data'!$L$2:$L$51,'Customer Data'!$U$2:$U$51,">0",'Customer Data'!$U$2:$U$51,"<="&D$3,'Customer Data'!$X$2:$X$51,">"&D$3) -> 781 | E7: =SUMIFS('Customer Data'!$L$2:$L$51,'Customer Data'!$U$2:$U$51,">0",'Customer Data'!$U$2:$U$51,"<="&E$3,'Customer Data'!$X$2:$X$51,">"&E$3) -> 1419 | F7: =SUMIFS('Customer Data'!$L$2:$L$51,'Customer Data'!$U$2:$U$51,">0",'Customer Data'!$U$2:$U$51,"<="&F$3,'Customer Data'!$X$2:$X$51,">"&F$3) -> 1915 | G7: =SUMIFS('Customer Data'!$L$2:$L$51,'Customer Data'!$U$2:$U$51,">0",'Customer Data'!$U$2:$U$51,"<="&G$3,'Customer Data'!$X$2:$X$51,">"&G$3) -> 2219 | H7: =SUMIFS('Customer Data'!$L$2:$L$51,'Customer Data'!$U$2:$U$51,">0",'Customer Data'!$U$2:$U$51,"<="&H$3,'Customer Data'!$X$2:$X$51,">"&H$3) -> 2820 | I7: =SUMIFS('Customer Data'!$L$2:$L$51,'Customer Data'!$U$2:$U$51,">0",'Customer Data'!$U$2:$U$51,"<="&I$3,'Customer Data'!$X$2:$X$51,">"&I$3) -> 3298 | ... Y7: =SUMIFS('Customer Data'!$L$2:$L$51,'Customer Data'!$U$2:$U$51,">0",'Customer Data'!$U$2:$U$51,"<="&Y$3,'Customer Data'!$X$2:$X$51,">"&Y$3) -> 2803
A8: Total Billings ($) | B8: =SUM(B5:B7) -> 20927 | C8: =SUM(C5:C7) -> 28021 | D8: =SUM(D5:D7) -> 10853 | E8: =SUM(E5:E7) -> 17085 | F8: =SUM(F5:F7) -> 18079 | G8: =SUM(G5:G7) -> 18880 | H8: =SUM(H5:H7) -> 15879 | I8: =SUM(I5:I7) -> 23340 | ... Y8: =SUM(Y5:Y7) -> 10272
A10: Revenue Recognized - Monthly Base ($) | B10: =B6 -> 1692 | C10: =C6 -> 2690 | D10: =D6 -> 4084 | E10: =E6 -> 6078 | F10: =F6 -> 6576 | G10: =G6 -> 7073 | H10: =H6 -> 7071 | I10: =I6 -> 8066 | ... Y10: =Y6 -> 7469
A11: Revenue Recognized - Annual Base ($) | B11: =SUMIFS('Customer Data'!$K$2:$K$51,'Customer Data'!$H$2:$H$51,"Annual",'Customer Data'!$T$2:$T$51,"<="&B$3,'Customer Data'!$X$2:$X$51,">"&B$3) -> 1598 | C11: =SUMIFS('Customer Data'!$K$2:$K$51,'Customer Data'!$H$2:$H$51,"Annual",'Customer Data'!$T$2:$T$51,"<="&C$3,'Customer Data'!$X$2:$X$51,">"&C$3) -> 3695 | D11: =SUMIFS('Customer Data'!$K$2:$K$51,'Customer Data'!$H$2:$H$51,"Annual",'Customer Data'!$T$2:$T$51,"<="&D$3,'Customer Data'!$X$2:$X$51,">"&D$3) -> 4194 | E11: =SUMIFS('Customer Data'!$K$2:$K$51,'Customer Data'!$H$2:$H$51,"Annual",'Customer Data'!$T$2:$T$51,"<="&E$3,'Customer Data'!$X$2:$X$51,">"&E$3) -> 4993 | F11: =SUMIFS('Customer Data'!$K$2:$K$51,'Customer Data'!$H$2:$H$51,"Annual",'Customer Data'!$T$2:$T$51,"<="&F$3,'Customer Data'!$X$2:$X$51,">"&F$3) -> 5792 | G11: =SUMIFS('Customer Data'!$K$2:$K$51,'Customer Data'!$H$2:$H$51,"Annual",'Customer Data'!$T$2:$T$51,"<="&G$3,'Customer Data'!$X$2:$X$51,">"&G$3) -> 6591 | H11: =SUMIFS('Customer Data'!$K$2:$K$51,'Customer Data'!$H$2:$H$51,"Annual",'Customer Data'!$T$2:$T$51,"<="&H$3,'Customer Data'!$X$2:$X$51,">"&H$3) -> 7090 | I11: =SUMIFS('Customer Data'!$K$2:$K$51,'Customer Data'!$H$2:$H$51,"Annual",'Customer Data'!$T$2:$T$51,"<="&I$3,'Customer Data'!$X$2:$X$51,">"&I$3) -> 8088 | ... Y11: =SUMIFS('Customer Data'!$K$2:$K$51,'Customer Data'!$H$2:$H$51,"Annual",'Customer Data'!$T$2:$T$51,"<="&Y$3,'Customer Data'!$X$2:$X$51,">"&Y$3) -> 0
A12: Revenue Recognized - Add-ons ($) | B12: =B7 -> 59 | C12: =C7 -> 167 | D12: =D7 -> 781 | E12: =E7 -> 1419 | F12: =F7 -> 1915 | G12: =G7 -> 2219 | H12: =H7 -> 2820 | I12: =I7 -> 3298 | ... Y12: =Y7 -> 2803
A13: Total Revenue Recognized ($) | B13: =SUM(B10:B12) -> 3349 | C13: =SUM(C10:C12) -> 6552 | D13: =SUM(D10:D12) -> 9059 | E13: =SUM(E10:E12) -> 12490 | F13: =SUM(F10:F12) -> 14283 | G13: =SUM(G10:G12) -> 15883 | H13: =SUM(H10:H12) -> 16981 | I13: =SUM(I10:I12) -> 19452 | ... Y13: =SUM(Y10:Y12) -> 10272
A15: Ending Deferred Revenue ($) | B15: =B8-B13 -> 17578 | C15: =B15+C8-C13 -> 39047 | D15: =C15+D8-D13 -> 40841 | E15: =D15+E8-E13 -> 45436 | F15: =E15+F8-F13 -> 49232 | G15: =F15+G8-G13 -> 52229 | H15: =G15+H8-H13 -> 51127 | I15: =H15+I8-I13 -> 55015 | J15: =I15+J8-J13 -> 46927 | ... Y15: =X15+Y8-Y13 -> 0

Sheet Segmentation
A1: Customer Segmentation
A3: Plan Mix
A4: Plan Tier | B4: Customers | C4: Active Customers | D4: Full-Ramp MRR ($)
A5: Starter | B5: =COUNTIF('Customer Data'!$F$2:$F$51,A5) -> 14 | C5: =COUNTIFS('Customer Data'!$F$2:$F$51,A5,'Customer Data'!$P$2:$P$51,"Active") -> 14 | D5: =SUMIF('Customer Data'!$F$2:$F$51,A5,'Customer Data'!$N$2:$N$51) -> 3030
A6: Growth | B6: =COUNTIF('Customer Data'!$F$2:$F$51,A6) -> 9 | C6: =COUNTIFS('Customer Data'!$F$2:$F$51,A6,'Customer Data'!$P$2:$P$51,"Active") -> 9 | D6: =SUMIF('Customer Data'!$F$2:$F$51,A6,'Customer Data'!$N$2:$N$51) -> 2686
A7: Pro | B7: =COUNTIF('Customer Data'!$F$2:$F$51,A7) -> 8 | C7: =COUNTIFS('Customer Data'!$F$2:$F$51,A7,'Customer Data'!$P$2:$P$51,"Active") -> 8 | D7: =SUMIF('Customer Data'!$F$2:$F$51,A7,'Customer Data'!$N$2:$N$51) -> 2866
A8: Business | B8: =COUNTIF('Customer Data'!$F$2:$F$51,A8) -> 11 | C8: =COUNTIFS('Customer Data'!$F$2:$F$51,A8,'Customer Data'!$P$2:$P$51,"Active") -> 11 | D8: =SUMIF('Customer Data'!$F$2:$F$51,A8,'Customer Data'!$N$2:$N$51) -> 6484
A9: Enterprise | B9: =COUNTIF('Customer Data'!$F$2:$F$51,A9) -> 8 | C9: =COUNTIFS('Customer Data'!$F$2:$F$51,A9,'Customer Data'!$P$2:$P$51,"Active") -> 8 | D9: =SUMIF('Customer Data'!$F$2:$F$51,A9,'Customer Data'!$N$2:$N$51) -> 7069
A12: Billing Mix
A13: Billing Type | B13: Customers | C13: Base ARR ($) | D13: Share %
A14: Monthly | B14: =COUNTIF('Customer Data'!$H$2:$H$51,A14) -> 38 | C14: =SUMIF('Customer Data'!$H$2:$H$51,A14,'Customer Data'!$S$2:$S$51) -> 0 | D14: =IF(SUM($B$14:$B$15)=0,"",B14/SUM($B$14:$B$15)) -> 0.76
A15: Annual | B15: =COUNTIF('Customer Data'!$H$2:$H$51,A15) -> 12 | C15: =SUMIF('Customer Data'!$H$2:$H$51,A15,'Customer Data'!$S$2:$S$51) -> 97056 | D15: =IF(SUM($B$14:$B$15)=0,"",B15/SUM($B$14:$B$15)) -> 0.24
A18: Customer Segment Mix
A19: Segment | B19: Customers | C19: Active Customers | D19: Avg Full-Ramp MRR ($)
A20: SMB | B20: =COUNTIF('Customer Data'!$G$2:$G$51,A20) -> 23 | C20: =COUNTIFS('Customer Data'!$G$2:$G$51,A20,'Customer Data'!$P$2:$P$51,"Active") -> 23 | D20: =IF(B20=0,"",SUMIF('Customer Data'!$G$2:$G$51,A20,'Customer Data'!$N$2:$N$51)/B20) -> 248.52174
A21: Mid-Market | B21: =COUNTIF('Customer Data'!$G$2:$G$51,A21) -> 19 | C21: =COUNTIFS('Customer Data'!$G$2:$G$51,A21,'Customer Data'!$P$2:$P$51,"Active") -> 19 | D21: =IF(B21=0,"",SUMIF('Customer Data'!$G$2:$G$51,A21,'Customer Data'!$N$2:$N$51)/B21) -> 492.10526
A22: Enterprise | B22: =COUNTIF('Customer Data'!$G$2:$G$51,A22) -> 8 | C22: =COUNTIFS('Customer Data'!$G$2:$G$51,A22,'Customer Data'!$P$2:$P$51,"Active") -> 8 | D22: =IF(B22=0,"",SUMIF('Customer Data'!$G$2:$G$51,A22,'Customer Data'!$N$2:$N$51)/B22) -> 883.625

Sheet Dashboard
A1: SaaS KPI Dashboard | Portfolio Case: Math of SaaS + Revenue Recognition
A2: Purpose | B2: Demonstrate automated SaaS KPI modeling from 50 mock subscription customers with clean MRR, CAC, LTV, cohort, and revenue recognition logic.
B4: Total Customers | D4: Active Customers | F4: Current MRR ($) | H4: ARR ($)
B5: =COUNTA('Customer Data'!A:A)-1 -> 50 | D5: =COUNTIF('Customer Data'!P:P,"Active") -> 50 | F5: ='Monthly Waterfall'!M15 -> 19852 | H5: =F5*12 -> 238224
B8: New MRR YTD ($) | D8: Expansion MRR YTD ($) | F8: Churn MRR YTD ($) | H8: Net New MRR YTD ($)
B9: =SUM('Monthly Waterfall'!B11:M11) -> 17450 | D9: =SUM('Monthly Waterfall'!B12:M12) -> 4685 | F9: =SUM('Monthly Waterfall'!B13:M13) -> 2283 | H9: =SUM('Monthly Waterfall'!B14:M14) -> 19852
B12: Gross Margin % | D12: ARPA ($) | F12: Avg CAC ($) | H12: CAC Payback (Months)
B13: =Assumptions!B5 -> 0.8 | D13: =IF(D5=0,"",F5/D5) -> 397.04 | F13: =SUM(Assumptions!C4:C15)/SUM('Monthly Waterfall'!B6:M6) -> 10822.44 | H13: =IF(OR(F13=0,D13=0,B13=0),"",F13/(D13*B13)) -> 34.07226
B16: Avg Monthly Logo Churn | D16: LTV ($) | F16: LTV:CAC | H16: Avg NRR
B17: =AVERAGE('Monthly Waterfall'!C17:M17) -> 0.022879676 | D17: =IF(B17=0,"",D13*B13/B17) -> 13882.714 | F17: =IF(F13=0,"",D17/F13) -> 1.2827712 | H17: =AVERAGE('Monthly Waterfall'!C19:M19) -> 1.018614
B20: Current Month NRR | D20: Best Month NRR | F20: Months ≥ 100%
B21: ='Monthly Waterfall'!M19 -> 0.98835009 | D21: =MAX('Monthly Waterfall'!B19:M19) -> 1.0937118 | F21: =COUNTIF('Monthly Waterfall'!B19:M19,">=1") -> 7
A24: Model Notes
A25: • New MRR = base plan MRR activated in the customer start month.
A26: • Expansion MRR = add-on MRR activated in the assigned expansion month.
A27: • Churn MRR = full-ramp MRR removed in the churn month.
A28: • LTV = ARPA × Gross Margin ÷ average monthly logo churn.
A29: • CAC = total 2023 Sales & Marketing spend ÷ total new customers acquired in 2023.
A30: • Revenue recognition treats annual base plans as upfront billings recognized ratably; add-ons are billed monthly.
H41: Original issue chart embedded for context

Sheet README
A1: How to Use This Workbook
A3: Goal | B3: Show commercial fluency in SaaS metrics, not just bookkeeping.
A5: 1. Customer Data | B5: Concrete 50-customer mock dataset with corrected cohort month, billing mix, and expansion timing.
A7: 2. Monthly Waterfall | B7: Automated New MRR, Expansion MRR, Churn MRR, ending MRR, churn %, NRR, and CAC by month.
A9: 3. Dashboard | B9: Executive summary view for interview or portfolio screenshots.
A11: 4. Revenue Recognition | B11: Annual base plans billed upfront and recognized monthly; add-ons billed monthly.
A13: 5. What is assumed | B13: Events are modeled at the month level to keep the template auditable and recruiter-friendly.
